Workbook

Sheet Dashboard
A1: PDM BINGOLON
A3: DUN | B3: DAERAH MENGUNDI | C3: BILANGAN PENGUNDI BERDAFTAR | D3: Anggaran Peratusan Turun Mengundi (75%) | E3: Sasaran UNDI 60% | F3: SASARAN KETUA KELUARGA (K10) | G3: JUMLAH K10 TERKINI | H3: PUTIH TERKINI | I3: Atas Pagar | J3: HITAM | K3: TIDAK KENAL | L3: Meninggal Dunia | M3: Pengundi Luar PARLIMEN | N3: Pengundi Luar SABAH | O3: PECAHAN PENGUNDI MENGIKUT UMUR
O4: 18 - 30 | P4: 31 - 45 | Q4: 46 - KEATAS
A5: BINGOLON | B5: KG BINGOLON | C5: =SUM('PENGUNDI BINGOLON'!U2:U593) -> 592 | D5: =C5*75/100 -> 444 | E5: =SUM(D5*55/100) -> 244.2 | F5: =SUM(E5/10) -> 24.42 | G5: =SUM('PENGUNDI BINGOLON'!K2:K593) -> 0 | H5: =SUM('PENGUNDI BINGOLON'!L2:L593) -> 0 | I5: =SUM('PENGUNDI BINGOLON'!M2:M593) -> 0 | J5: =SUM('PENGUNDI BINGOLON'!N2:N593) -> 0 | K5: =SUM('PENGUNDI BINGOLON'!O2:O593) -> 0 | L5: =SUM('PENGUNDI BINGOLON'!P2:P593) -> 0 | M5: =SUM('PENGUNDI BINGOLON'!Q2:Q593) -> 0 | N5: =SUM('PENGUNDI BINGOLON'!R2:R593) -> 0
B6: KG PANUDAHAU | C6: =SUM('PENGUNDI BINGOLON'!U594:U625) -> 32 | D6: =C6*75/100 -> 24 | E6: =SUM(D6*55/100) -> 13.2 | F6: =SUM(E6/10) -> 1.32 | G6: =SUM('PENGUNDI BINGOLON'!K594:K625) -> 0 | H6: =SUM('PENGUNDI BINGOLON'!L594:L625) -> 0 | I6: =SUM('PENGUNDI BINGOLON'!M594:M625) -> 0 | J6: =SUM('PENGUNDI BINGOLON'!N594:N625) -> 0 | K6: =SUM('PENGUNDI BINGOLON'!O594:O625) -> 0 | L6: =SUM('PENGUNDI BINGOLON'!P594:P625) -> 0 | M6: =SUM('PENGUNDI BINGOLON'!Q594:Q625) -> 0 | N6: =SUM('PENGUNDI BINGOLON'!R594:R625) -> 0
A7: JUMLAH | C7: =SUM(C5:C6) -> 624 | D7: =SUM(D5:D6) -> 468 | E7: =SUM(E5:E6) -> 257.4 | F7: =SUM(F5:F6) -> 25.74 | G7: =SUM(G5:G6) -> 0 | H7: =SUM(H5:H6) -> 0 | I7: =SUM(I5:I6) -> 0 | J7: =SUM(J5:J6) -> 0 | ... Q7: =SUM(Q5:Q6) -> 0

Sheet PENGUNDI BINGOLON
A1: NO | B1: NO KP | C1: IC LAMA | D1: S | E1: LAHIR | F1: NAMA PENUH | G1: PARLIMEN | H1: DM | I1: LOKALITI | J1: NO TELEFON | K1: K10 | L1: P | M1: AP | N1: H | O1: TAK KENAL | P1: X DUNIA | Q1: SABAH LABUAN | R1: LUAR SABAH | S1: Perincian | T1: TAGING | U1: D | V1: TAMBANG | W1: SEWA KERETA | X1: Delivered
A2: 1 | B2: 201126125003 | C2: H0262206 | D2: L | E2: 1920 | F2: LENFOOK BIN UMPOT | G2: KOTA MARUDU | H2: BINGOLON | I2: KG BINGOLON | U2: 1
A3: 2 | B3: 331112125366 | C3: H0262205 | D3: P | E3: 1933 | F3: TALUMA BINTI ONGMUT | G3: KOTA MARUDU | H3: BINGOLON | I3: KG BINGOLON | U3: 1
A4: 3 | B4: 341129125150 | C4: H0247282 | D4: P | E4: 1934 | F4: ROMBIYEN BINTI MONGISAN | G4: KOTA MARUDU | H4: BINGOLON | I4: KG BINGOLON | U4: 1
A5: 4 | B5: 341129125302 | C5: H0266605 | D5: P | E5: 1934 | F5: YANGAU BINTI BANSUL | G5: KOTA MARUDU | H5: BINGOLON | I5: KG BINGOLON | U5: 1
A6: 5 | B6: 361124125096 | C6: H0165570 | D6: P | E6: 1936 | F6: MONGOLIHIT BINTI SORUBIL | G6: KOTA MARUDU | H6: BINGOLON | I6: KG BINGOLON | U6: 1
A7: 6 | B7: 380807125056 | C7: H0165576 | D7: P | E7: 1938 | F7: ENALESAN BINTI GAZOT | G7: KOTA MARUDU | H7: BINGOLON | I7: KG BINGOLON | U7: 1
A8: 7 | B8: 391012125152 | C8: H0160512 | D8: P | E8: 1939 | F8: LANUN BINTI MONUPANG | G8: KOTA MARUDU | H8: BINGOLON | I8: KG BINGOLON | U8: 1
A9: 8 | B9: 410125125168 | C9: H0266604 | D9: P | E9: 1941 | F9: ARAMBAI BINTI SABOIN | G9: KOTA MARUDU | H9: BINGOLON | I9: KG BINGOLON | U9: 1
A10: 9 | B10: 410617125164 | C10: H0261145 | D10: P | E10: 1941 | F10: DOLINHAK BINTI KOLUMBAI | G10: KOTA MARUDU | H10: BINGOLON | I10: KG BINGOLON | U10: 1
A11: 10 | B11: 440109125157 | C11: H0327948 | D11: L | E11: 1944 | F11: PUTOK BIN ARU | G11: KOTA MARUDU | H11: BINGOLON | I11: KG BINGOLON | U11: 1
A12: 11 | B12: 481204125199 | C12: H0285616 | D12: L | E12: 1948 | F12: UNKAR BIN MASAPAN | G12: KOTA MARUDU | H12: BINGOLON | I12: KG BINGOLON | U12: 1
A13: 12 | B13: 511030125221 | C13: H0224334 | D13: L | E13: 1951 | F13: AKMARLIM BIN JAMA | G13: KOTA MARUDU | H13: BINGOLON | I13: KG BINGOLON | U13: 1
... A68: 67 | B68: 700531125724 | C68: H0800056 | D68: P | E68: 1970 | F68: RISLIAH BINTI MONGINTAP @ ONGINTAP | G68: KOTA MARUDU | H68: BINGOLON | I68: KG BINGOLON | U68: 1
A69: 68 | B69: 700812125544 | D69: P | E69: 1970 | F69: MAINAH BINTI MOLISUN | G69: KOTA MARUDU | H69: BINGOLON | I69: KG BINGOLON | U69: 1
A70: 69 | B70: 701111125861 | C70: H0872422 | D70: L | E70: 1970 | F70: MAJUNING @ RENDY BIN UENSAI | G70: KOTA MARUDU | H70: BINGOLON | I70: KG BINGOLON | U70: 1
A71: 70 | B71: 710227125411 | C71: H0773793 | D71: L | E71: 1971 | F71: JOHNY BIN MOJULING | G71: KOTA MARUDU | H71: BINGOLON | I71: KG BINGOLON | U71: 1
A72: 71 | B72: 720104125883 | C72: H0810659 | D72: L | E72: 1972 | F72: JOHNY BIN YENTAN @ JOHNY BIN ANTAN | G72: KOTA MARUDU | H72: BINGOLON | I72: KG BINGOLON | U72: 1
A73: 72 | B73: 720201125156 | C73: H0870211 | D73: P | E73: 1972 | F73: NORUMI BINTI UNKAR | G73: KOTA MARUDU | H73: BINGOLON | I73: KG BINGOLON | U73: 1
A74: 73 | B74: 720617125141 | D74: L | E74: 1972 | F74: MATUS BIN RUTUM | G74: KOTA MARUDU | H74: BINGOLON | I74: KG BINGOLON | U74: 1
A75: 74 | B75: 721101125217 | C75: H0817029 | D75: L | E75: 1972 | F75: HALIM BIN JAMA | G75: KOTA MARUDU | H75: BINGOLON | I75: KG BINGOLON | U75: 1
A76: 75 | B76: 730107125474 | C76: H0864740 | D76: P | E76: 1973 | F76: KATIAH BINTI KAMPUN | G76: KOTA MARUDU | H76: BINGOLON | I76: KG BINGOLON | U76: 1
A77: 76 | B77: 730825125460 | C77: H0864742 | D77: P | E77: 1973 | F77: KASMAH BINTI TOVIL | G77: KOTA MARUDU | H77: BINGOLON | I77: KG BINGOLON | U77: 1
A78: 77 | B78: 740419125018 | D78: P | E78: 1974 | F78: KATIAH BINTI ONGIKAL | G78: KOTA MARUDU | H78: BINGOLON | I78: KG BINGOLON | U78: 1
A79: 78 | B79: 740528125009 | C79: H0960262 | D79: L | E79: 1974 | F79: JOMIEN @ FELLY MAJALI BIN YENTAN | G79: KOTA MARUDU | H79: BINGOLON | I79: KG BINGOLON | U79: 1
A80: 79 | B80: 740801125211 | C80: H0934360 | D80: L | E80: 1974 | F80: AIDI BIN HASSAN | G80: KOTA MARUDU | H80: BINGOLON | I80: KG BINGOLON | U80: 1
A81: 80 | B81: 750112125098 | C81: H0934364 | D81: P | E81: 1975 | F81: MARIA BINTI UNKAR | G81: KOTA MARUDU | H81: BINGOLON | I81: KG BINGOLON | U81: 1
A82: 81 | B82: 750503125183 | D82: L | E82: 1975 | F82: RICO RAYLIKO ONGIKAL | G82: KOTA MARUDU | H82: BINGOLON | I82: KG BINGOLON | U82: 1
A83: 82 | B83: 760316125873 | D83: L | E83: 1976 | F83: JAFRY BIN ALIM | G83: KOTA MARUDU | H83: BINGOLON | I83: KG BINGOLON | U83: 1
A84: 83 | B84: 760420126083 | C84: H0960342 | D84: L | E84: 1976 | F84: JOMINOL BIN MORIDING | G84: KOTA MARUDU | H84: BINGOLON | I84: KG BINGOLON | U84: 1
A85: 84 | B85: 760607125515 | D85: L | E85: 1976 | F85: EMBRAN BIN ABDUL MANAN | G85: KOTA MARUDU | H85: BINGOLON | I85: KG BINGOLON | U85: 1
A86: 85 | B86: 770103125377 | D86: L | E86: 1977 | F86: ILING BIN ONGIKAL | G86: KOTA MARUDU | H86: BINGOLON | I86: KG BINGOLON | U86: 1
A87: 86 | B87: 781111125901 | D87: L | E87: 1978 | F87: JOIN BIN ONGIKAL | G87: KOTA MARUDU | H87: BINGOLON | I87: KG BINGOLON | U87: 1
A88: 87 | B88: 791012126078 | D88: P | E88: 1979 | F88: ROSSILINA BINTI RUTUM | G88: KOTA MARUDU | H88: BINGOLON | I88: KG BINGOLON | U88: 1
A89: 88 | B89: 000111120591 | D89: L | E89: 2000 | F89: ALEXTO BIN JOHN | G89: KOTA MARUDU | H89: BINGOLON | I89: KG BINGOLON | U89: 1
A90: 89 | B90: 000203120441 | D90: L | E90: 2000 | F90: KENDY JOKIUS | G90: KOTA MARUDU | H90: BINGOLON | I90: KG BINGOLON | U90: 1
A91: 90 | B91: 000206120121 | D91: L | E91: 2000 | F91: REVALINO JONING | G91: KOTA MARUDU | H91: BINGOLON | I91: KG BINGOLON | U91: 1
A92: 91 | B92: 000624120431 | D92: L | E92: 2000 | F92: ELVIN LADIN | G92: KOTA MARUDU | H92: BINGOLON | I92: KG BINGOLON | U92: 1
A93: 92 | B93: 000703120536 | D93: P | E93: 2000 | F93: CE CHIA DRAGON | G93: KOTA MARUDU | H93: BINGOLON | I93: KG BINGOLON | U93: 1
A94: 93 | B94: 000710121203 | D94: L | E94: 2000 | F94: RAVIE BIN ALMAN | G94: KOTA MARUDU | H94: BINGOLON | I94: KG BINGOLON | U94: 1
...
