Workbook

Sheet Dashboard
A1: DASHBOARD PDM LAJONG
A3: DM | B3: LOKALITI | C3: BILANGAN PENGUNDI BERDAFTAR | D3: Anggaran Peratusan Turun Mengundi (75%) | E3: Sasaran UNDI 60% | F3: SASARAN KETUA KELUARGA (K10) | G3: JUMLAH K10 TERKINI | H3: PUTIH TERKINI | I3: Atas Pagar | J3: HITAM | K3: TIDAK KENAL | L3: Meninggal Dunia | M3: Pengundi Luar PARLIMEN | N3: Pengundi Luar SABAH | O3: PECAHAN PENGUNDI MENGIKUT UMUR
O4: 18 - 30 | P4: 31 - 45 | Q4: 46 - KEATAS
A5: LAJONG | B5: TINUTUDAN | C5: =SUM('PDM LAJONG'!V2:V204) -> 203 | D5: =C5*75/100 -> 152.25 | E5: =SUM(D5*55/100) -> 83.7375 | F5: =SUM(E5/10) -> 8.37375 | G5: =SUM('PDM LAJONG'!L2:L204) -> 0 | H5: =SUM('PDM LAJONG'!M2:M204) -> 0 | I5: =SUM('PDM LAJONG'!N2:N204) -> 0 | J5: =SUM('PDM LAJONG'!O2:O204) -> 0 | K5: =SUM('PDM LAJONG'!P2:P204) -> 0 | L5: =SUM('PDM LAJONG'!Q2:Q204) -> 0 | M5: =SUM('PDM LAJONG'!R2:R204) -> 0 | N5: =SUM('PDM LAJONG'!S2:S204) -> 0
B6: LAJONG | C6: =SUM('PDM LAJONG'!V205:V971) -> 767 | D6: =C6*75/100 -> 575.25 | E6: =SUM(D6*55/100) -> 316.3875 | F6: =SUM(E6/10) -> 31.63875 | G6: =SUM('PDM LAJONG'!L205:L971) -> 0 | H6: =SUM('PDM LAJONG'!M205:M971) -> 0 | I6: =SUM('PDM LAJONG'!N205:N971) -> 0 | J6: =SUM('PDM LAJONG'!O205:O971) -> 0 | K6: =SUM('PDM LAJONG'!P205:P971) -> 0 | L6: =SUM('PDM LAJONG'!Q205:Q971) -> 0 | M6: =SUM('PDM LAJONG'!R205:R971) -> 0 | N6: =SUM('PDM LAJONG'!S205:S971) -> 0
A7: JUMLAH | C7: =SUM(C5:C6) -> 970 | D7: =SUM(D5:D6) -> 727.5 | E7: =SUM(E5:E6) -> 400.125 | F7: =SUM(F5:F6) -> 40.0125 | G7: =SUM(G5:G6) -> 0 | H7: =SUM(H5:H6) -> 0 | I7: =SUM(I5:I6) -> 0 | J7: =SUM(J5:J6) -> 0 | ... M7: =SUM(M5:M6) -> 0 | O7: =SUM(O5:O6) -> 0 | P7: =SUM(P5:P6) -> 0 | Q7: =SUM(Q5:Q6) -> 0

Sheet PDM LAJONG
A1: NO | B1: NO KP | C1: IC LAMA | D1: S | E1: LAHIR | F1: NAMA PENUH | G1: PARLIMEN | H1: DUN | I1: DM | J1: LOKALITI | K1: NO TELEFON | L1: K10 | M1: P | N1: AP | O1: H | P1: TAK KENAL | Q1: X DUNIA | R1: SABAH LABUAN | S1: LUAR SABAH | T1: Perincian | U1: TAGING | V1: D | W1: TAMBANG | X1: SEWA KERETA | Y1: Delivered
A2: 1 | B2: 440916125276 | C2: H0056570 | D2: P | E2: 1944 | F2: PANG YET KYAU @ PANG THAU KYAU | G2: KOTA MARUDU | H2: MATUNGGONG | I2: LAJONG | J2: KG TINUTUDAN | V2: 1
A3: 2 | B3: 480115125299 | C3: H0278206 | D3: L | E3: 1948 | F3: UROK BIN UPONG | G3: KOTA MARUDU | H3: MATUNGGONG | I3: LAJONG | J3: KG TINUTUDAN | V3: 1
A4: 3 | B4: 511230125285 | C4: H0264838 | D4: L | E4: 1951 | F4: OSEWAN BIN AYONG | G4: KOTA MARUDU | H4: MATUNGGONG | I4: LAJONG | J4: KG TINUTUDAN | V4: 1
A5: 4 | B5: 521209125538 | C5: H0260578 | D5: P | E5: 1952 | F5: INDAYIU BINTI UENSAI | G5: KOTA MARUDU | H5: MATUNGGONG | I5: LAJONG | J5: KG TINUTUDAN | V5: 1
A6: 5 | B6: 570615125825 | C6: H0428834 | D6: L | E6: 1957 | F6: MATIMBUN BIN KADUWAN | G6: KOTA MARUDU | H6: MATUNGGONG | I6: LAJONG | J6: KG TINUTUDAN | V6: 1
A7: 6 | B7: 601007125433 | C7: H0469107 | D7: L | E7: 1960 | F7: JOMILING MARATIM | G7: KOTA MARUDU | H7: MATUNGGONG | I7: LAJONG | J7: KG TINUTUDAN | V7: 1
A8: 7 | B8: 640606125533 | C8: H0637375 | D8: L | E8: 1964 | F8: DSEMI BIN MATANGKAP | G8: KOTA MARUDU | H8: MATUNGGONG | I8: LAJONG | J8: KG TINUTUDAN | V8: 1
A9: 8 | B9: 681126125033 | C9: H0716759 | D9: L | E9: 1968 | F9: MADEOS B.N.C ANGKANGON | G9: KOTA MARUDU | H9: MATUNGGONG | I9: LAJONG | J9: KG TINUTUDAN | V9: 1
A10: 9 | B10: 690729125483 | C10: H0716832 | D10: L | E10: 1969 | F10: JONING BIN MARAIM | G10: KOTA MARUDU | H10: MATUNGGONG | I10: LAJONG | J10: KG TINUTUDAN | V10: 1
A11: 10 | B11: 720222125585 | C11: H0868374 | D11: L | E11: 1972 | F11: LETANIS BIN MAJUBE | G11: KOTA MARUDU | H11: MATUNGGONG | I11: LAJONG | J11: KG TINUTUDAN | V11: 1
A12: 11 | B12: 740817125574 | C12: H0960326 | D12: P | E12: 1974 | F12: JUINI BINTI MAJUBE | G12: KOTA MARUDU | H12: MATUNGGONG | I12: LAJONG | J12: KG TINUTUDAN | V12: 1
A13: 12 | B13: 750220125570 | C13: H0907430 | D13: P | E13: 1975 | F13: ROSSEY BINTI MATIUS | G13: KOTA MARUDU | H13: MATUNGGONG | I13: LAJONG | J13: KG TINUTUDAN | V13: 1
... A15: 14 | B15: 760208125470 | C15: H0929418 | D15: P | E15: 1976 | F15: ROSE BINTI AKANDANG | G15: KOTA MARUDU | H15: MATUNGGONG | I15: LAJONG | J15: KG TINUTUDAN | V15: 1
A16: 15 | B16: 000114120589 | D16: L | E16: 2000 | F16: RICKO AZVEN BIN ATUNG | G16: KOTA MARUDU | H16: MATUNGGONG | I16: LAJONG | J16: KG TINUTUDAN | V16: 1
A17: 16 | B17: 000322120014 | D17: P | E17: 2000 | F17: VELLMA ERNICCA REVEUS | G17: KOTA MARUDU | H17: MATUNGGONG | I17: LAJONG | J17: KG TINUTUDAN | V17: 1
A18: 17 | B18: 000326120409 | D18: L | E18: 2000 | F18: CARL DYONY ND SELVOSIUS | G18: KOTA MARUDU | H18: MATUNGGONG | I18: LAJONG | J18: KG TINUTUDAN | V18: 1
A19: 18 | B19: 000518120526 | D19: P | E19: 2000 | F19: NORAANIZANISANIZA BINTI JULAIDI | G19: KOTA MARUDU | H19: MATUNGGONG | I19: LAJONG | J19: KG TINUTUDAN | V19: 1
A20: 19 | B20: 000616120538 | D20: P | E20: 2000 | F20: NURAFIQAH BINTI ASOI @ JOHN | G20: KOTA MARUDU | H20: MATUNGGONG | I20: LAJONG | J20: KG TINUTUDAN | V20: 1
A21: 20 | B21: 000721120927 | D21: L | E21: 2000 | F21: AIRON BIN MAIL | G21: KOTA MARUDU | H21: MATUNGGONG | I21: LAJONG | J21: KG TINUTUDAN | V21: 1
A22: 21 | B22: 000902121240 | D22: P | E22: 2000 | F22: RIZIA VERONICA BINTI ROJER | G22: KOTA MARUDU | H22: MATUNGGONG | I22: LAJONG | J22: KG TINUTUDAN | V22: 1
A23: 22 | B23: 001009121277 | D23: L | E23: 2000 | F23: DICKEY KONG HOI HIUNG | G23: KOTA MARUDU | H23: MATUNGGONG | I23: LAJONG | J23: KG TINUTUDAN | V23: 1
A24: 23 | B24: 001204121758 | D24: P | E24: 2000 | F24: CYNTHIA CHRISTINE HENRY | G24: KOTA MARUDU | H24: MATUNGGONG | I24: LAJONG | J24: KG TINUTUDAN | V24: 1
A25: 24 | B25: 010116120856 | D25: P | E25: 2001 | F25: AUDREY ALVERA BINTI ALFREED | G25: KOTA MARUDU | H25: MATUNGGONG | I25: LAJONG | J25: KG TINUTUDAN | V25: 1
A26: 25 | B26: 010125120436 | D26: P | E26: 2001 | F26: VANESSA LESLIE JEBIRING | G26: KOTA MARUDU | H26: MATUNGGONG | I26: LAJONG | J26: KG TINUTUDAN | V26: 1
A27: 26 | B27: 010601120016 | D27: P | E27: 2001 | F27: SHARIAH NOOR SHAZIAH BINTI SHAKIR | G27: KOTA MARUDU | H27: MATUNGGONG | I27: LAJONG | J27: KG TINUTUDAN | V27: 1
... A75: 76 | B75: 070814120524 | D75: P | E75: 2007 | F75: JACQUALYN JAIME JEBIRING | G75: KOTA MARUDU | H75: MATUNGGONG | I75: LAJONG | J75: KG TINUTUDAN | V75: 1
A76: 77 | B76: 550702125438 | C76: H0236500 | D76: P | E76: 1955 | F76: HELEN BINTI MAJURIP | G76: KOTA MARUDU | H76: MATUNGGONG | I76: LAJONG | J76: KG TINUTUDAN | V76: 1
A77: 78 | B77: 730527125681 | C77: H0865432 | D77: L | E77: 1973 | F77: LAUSSEN BIN ONGINDA | G77: KOTA MARUDU | H77: MATUNGGONG | I77: LAJONG | J77: KG TINUTUDAN | V77: 1
A78: 79 | B78: 760218125212 | C78: H6038656 | D78: P | E78: 1976 | F78: SORURUL BINTI RASID | G78: KOTA MARUDU | H78: MATUNGGONG | I78: LAJONG | J78: KG TINUTUDAN | V78: 1
A79: 80 | B79: 770804126014 | D79: P | E79: 1977 | F79: FELIN INOK | G79: KOTA MARUDU | H79: MATUNGGONG | I79: LAJONG | J79: KG TINUTUDAN | V79: 1
A80: 84 | B80: 790912126191 | D80: L | E80: 1979 | F80: BONY DIUN | G80: KOTA MARUDU | H80: MATUNGGONG | I80: LAJONG | J80: KG TINUTUDAN | V80: 1
A81: 87 | B81: 810101126265 | D81: L | E81: 1981 | F81: EDMOND BIN PALINU @ PAUL | G81: KOTA MARUDU | H81: MATUNGGONG | I81: LAJONG | J81: KG TINUTUDAN | V81: 1
A82: 89 | B82: 820315125558 | D82: P | E82: 1982 | F82: ANNIE BINTI INOL @ THOMAS | G82: KOTA MARUDU | H82: MATUNGGONG | I82: LAJONG | J82: KG TINUTUDAN | V82: 1
A83: 90 | B83: 821022126201 | D83: L | E83: 1982 | F83: DONNYWIN BIN MOLISUN | G83: KOTA MARUDU | H83: MATUNGGONG | I83: LAJONG | J83: KG TINUTUDAN | V83: 1
A84: 91 | B84: 821216125549 | D84: L | E84: 1982 | F84: JAMES BIN ONGINDA | G84: KOTA MARUDU | H84: MATUNGGONG | I84: LAJONG | J84: KG TINUTUDAN | V84: 1
A85: 92 | B85: 830917125634 | D85: P | E85: 1983 | F85: JOANNA AUDREY PALINU PAUL | G85: KOTA MARUDU | H85: MATUNGGONG | I85: LAJONG | J85: KG TINUTUDAN | V85: 1
A86: 93 | B86: 840508126205 | D86: L | E86: 1984 | F86: DJACKRIN BIN JAIKOP | G86: KOTA MARUDU | H86: MATUNGGONG | I86: LAJONG | J86: KG TINUTUDAN | V86: 1
A87: 94 | B87: 840614125900 | D87: P | E87: 1984 | F87: CALARIE BINTI DIUN | G87: KOTA MARUDU | H87: MATUNGGONG | I87: LAJONG | J87: KG TINUTUDAN | V87: 1
A88: 95 | B88: 850403125598 | D88: P | E88: 1985 | F88: MELLY K.V ROBERT LIM | G88: KOTA MARUDU | H88: MATUNGGONG | I88: LAJONG | J88: KG TINUTUDAN | V88: 1
...
