Workbook

Sheet Dashboard
A1: DASHBOARD PDM INDARASON
A3: DM | B3: LOKALITI | C3: BILANGAN PENGUNDI BERDAFTAR | D3: Anggaran Peratusan Turun Mengundi (75%) | E3: Sasaran UNDI 60% | F3: SASARAN KETUA KELUARGA (K10) | G3: JUMLAH K10 TERKINI | H3: PUTIH TERKINI | I3: Atas Pagar | J3: HITAM | K3: TIDAK KENAL | L3: Meninggal Dunia | M3: Pengundi Luar PARLIMEN | N3: Pengundi Luar SABAH | O3: PECAHAN PENGUNDI MENGIKUT UMUR
O4: 18 - 30 | P4: 31 - 45 | Q4: 46 - KEATAS
A5: INDARASON | B5: KG INDARASON | C5: =SUM('PDM INDARASON'!V2:V630) -> 629 | D5: =C5*75/100 -> 471.75 | E5: =SUM(D5*55/100) -> 259.4625 | F5: =SUM(E5/10) -> 25.94625 | G5: =SUM('PDM INDARASON'!L2:L630) -> 0 | H5: =SUM('PDM INDARASON'!M2:M630) -> 0 | I5: =SUM('PDM INDARASON'!N2:N630) -> 0 | J5: =SUM('PDM INDARASON'!O2:O630) -> 0 | K5: =SUM('PDM INDARASON'!P2:P630) -> 0 | L5: =SUM('PDM INDARASON'!Q2:Q630) -> 0 | M5: =SUM('PDM INDARASON'!R2:R630) -> 0 | N5: =SUM('PDM INDARASON'!S2:S630) -> 0
B6: KG INDARASON DARAT | C6: =SUM('PDM INDARASON'!V631:V827) -> 197 | D6: =C6*75/100 -> 147.75 | E6: =SUM(D6*55/100) -> 81.2625 | F6: =SUM(E6/10) -> 8.12625 | G6: =SUM('PDM INDARASON'!L631:L827) -> 0 | H6: =SUM('PDM INDARASON'!M631:M827) -> 0 | I6: =SUM('PDM INDARASON'!N631:N827) -> 0 | J6: =SUM('PDM INDARASON'!O631:O827) -> 0 | K6: =SUM('PDM INDARASON'!P631:P827) -> 0 | L6: =SUM('PDM INDARASON'!Q631:Q827) -> 0 | M6: =SUM('PDM INDARASON'!R631:R827) -> 0 | N6: =SUM('PDM INDARASON'!S631:S827) -> 0
B7: KG INDARASON LAUT | C7: =SUM('PDM INDARASON'!V828:V1245) -> 418 | D7: =C7*75/100 -> 313.5 | E7: =SUM(D7*55/100) -> 172.425 | F7: =SUM(E7/10) -> 17.2425 | G7: =SUM('PDM INDARASON'!L828:L1245) -> 0 | H7: =SUM('PDM INDARASON'!M828:M1245) -> 0 | I7: =SUM('PDM INDARASON'!N828:N1245) -> 0 | J7: =SUM('PDM INDARASON'!O828:O1245) -> 0 | K7: =SUM('PDM INDARASON'!P828:P1245) -> 0 | L7: =SUM('PDM INDARASON'!Q828:Q1245) -> 0 | M7: =SUM('PDM INDARASON'!R828:R1245) -> 0 | N7: =SUM('PDM INDARASON'!S828:S1245) -> 0
A8: JUMLAH | C8: =SUM(C5:C7) -> 1244 | D8: =SUM(D5:D7) -> 933 | E8: =SUM(E5:E7) -> 513.15 | F8: =SUM(F5:F7) -> 51.315 | G8: =SUM(G5:G7) -> 0 | H8: =SUM(H5:H7) -> 0 | I8: =SUM(I5:I7) -> 0 | J8: =SUM(J5:J7) -> 0 | ... Q8: =SUM(Q5:Q7) -> 0

Sheet PDM INDARASON
A1: NO | B1: NO KP | C1: IC LAMA | D1: S | E1: LAHIR | F1: NAMA PENUH | G1: PARLIMEN | H1: DUN | I1: DM | J1: LOKALITI | K1: NO TELEFON | L1: K10 | M1: P | N1: AP | O1: H | P1: TAK KENAL | Q1: X DUNIA | R1: SABAH LABUAN | S1: LUAR SABAH | T1: Perincian | U1: TAGING | V1: D | W1: TAMBANG | X1: SEWA KERETA | Y1: Delivered
A2: 1 | B2: 251219125294 | C2: H0138680 | D2: P | E2: 1925 | F2: UMBAWAK BINTI RAMBAYAU | G2: KOTA MARUDU | H2: MATUNGGONG | I2: INDARASON | J2: KG INDARASON | V2: 1
A3: 2 | B3: 270607125062 | C3: H0152773 | D3: P | E3: 1927 | F3: SAWANIL BINTI MANGNIJER | G3: KOTA MARUDU | H3: MATUNGGONG | I3: INDARASON | J3: KG INDARASON | V3: 1
A4: 3 | B4: 280906125088 | C4: H0060243 | D4: P | E4: 1928 | F4: MONGULIHAT BINTI MATAMIT | G4: KOTA MARUDU | H4: MATUNGGONG | I4: INDARASON | J4: KG INDARASON | V4: 1
A5: 4 | B5: 310626125088 | C5: H0163804 | D5: P | E5: 1931 | F5: BAHAYAN @ SURAYA BINTI BANSAL | G5: KOTA MARUDU | H5: MATUNGGONG | I5: INDARASON | J5: KG INDARASON | V5: 1
A6: 5 | B6: 310822125018 | C6: H0166339 | D6: P | E6: 1931 | F6: DIHURI BINTI BADYLAN | G6: KOTA MARUDU | H6: MATUNGGONG | I6: INDARASON | J6: KG INDARASON | V6: 1
A7: 6 | B7: 320214125005 | C7: H0096017 | D7: L | E7: 1932 | F7: YAKANG BIN WAKAP | G7: KOTA MARUDU | H7: MATUNGGONG | I7: INDARASON | J7: KG INDARASON | V7: 1
A8: 7 | B8: 330117125109 | C8: H0095999 | D8: L | E8: 1933 | F8: ALI BIN DUSIAK | G8: KOTA MARUDU | H8: MATUNGGONG | I8: INDARASON | J8: KG INDARASON | V8: 1
A9: 8 | B9: 330515125198 | C9: H0060854 | D9: P | E9: 1933 | F9: LINANGKAPAN BINTI MASUKUD | G9: KOTA MARUDU | H9: MATUNGGONG | I9: INDARASON | J9: KG INDARASON | V9: 1
A10: 9 | B10: 330520125272 | C10: H0117933 | D10: P | E10: 1933 | F10: JALIK BINTI EDAU | G10: KOTA MARUDU | H10: MATUNGGONG | I10: INDARASON | J10: KG INDARASON | V10: 1
A11: 10 | B11: 330524125122 | C11: H0096006 | D11: P | E11: 1933 | F11: SINAUWASAH BINTI MOKILIN | G11: KOTA MARUDU | H11: MATUNGGONG | I11: INDARASON | J11: KG INDARASON | V11: 1
A12: 11 | B12: 331101125176 | C12: H0163817 | D12: P | E12: 1933 | F12: LUMINZOY @ FATIMAH BINTI MONGINZAM | G12: KOTA MARUDU | H12: MATUNGGONG | I12: INDARASON | J12: KG INDARASON | V12: 1
A13: 12 | B13: 331125125189 | C13: H0166334 | D13: L | E13: 1933 | F13: AMELASA BIN ALUSMAN | G13: KOTA MARUDU | H13: MATUNGGONG | I13: INDARASON | J13: KG INDARASON | V13: 1
... A95: 94 | B95: 620306125074 | C95: H0761974 | D95: P | E95: 1962 | F95: MONGKUIZA BINTI MAGADAM | G95: KOTA MARUDU | H95: MATUNGGONG | I95: INDARASON | J95: KG INDARASON | V95: 1
A96: 95 | B96: 620312125046 | D96: P | E96: 1962 | F96: SITI MARIAM BINTI PERIK | G96: KOTA MARUDU | H96: MATUNGGONG | I96: INDARASON | J96: KG INDARASON | V96: 1
A97: 96 | B97: 620503125823 | C97: H0677001 | D97: L | E97: 1962 | F97: MADIN BIN ZANE | G97: KOTA MARUDU | H97: MATUNGGONG | I97: INDARASON | J97: KG INDARASON | V97: 1
A98: 97 | B98: 620830125337 | C98: H0750000 | D98: L | E98: 1962 | F98: FERDLY BIN ADZAIL | G98: KOTA MARUDU | H98: MATUNGGONG | I98: INDARASON | J98: KG INDARASON | V98: 1
A99: 98 | B99: 630207125422 | D99: P | E99: 1963 | F99: NAGISAN BINTI MABALI @ MAPARIT | G99: KOTA MARUDU | H99: MATUNGGONG | I99: INDARASON | J99: KG INDARASON | V99: 1
A100: 99 | B100: 630605125938 | C100: H0764326 | D100: P | E100: 1963 | F100: AISAH BINTI JALILUL | G100: KOTA MARUDU | H100: MATUNGGONG | I100: INDARASON | J100: KG INDARASON | V100: 1
A101: 100 | B101: 630805125924 | C101: H0443286 | D101: P | E101: 1963 | F101: FATIMAH BINTI SAPILIN | G101: KOTA MARUDU | H101: MATUNGGONG | I101: INDARASON | J101: KG INDARASON | V101: 1
A102: 101 | B102: 630812125308 | C102: H0689215 | D102: P | E102: 1963 | F102: SITAH BINTI MOHAMAT | G102: KOTA MARUDU | H102: MATUNGGONG | I102: INDARASON | J102: KG INDARASON | V102: 1
A103: 102 | B103: 630823125215 | C103: H0437588 | D103: L | E103: 1963 | F103: ASLI BIN ABD KARIM | G103: KOTA MARUDU | H103: MATUNGGONG | I103: INDARASON | J103: KG INDARASON | V103: 1
A104: 103 | B104: 631122125372 | C104: H0677588 | D104: P | E104: 1963 | F104: MARY BINTI JURUBAKAR | G104: KOTA MARUDU | H104: MATUNGGONG | I104: INDARASON | J104: KG INDARASON | V104: 1
A105: 104 | B105: 640401135594 | C105: K0170019 | D105: P | E105: 1964 | F105: RAHMAH BINTI BAKAR | G105: KOTA MARUDU | H105: MATUNGGONG | I105: INDARASON | J105: KG INDARASON | V105: 1
A106: 105 | B106: 640416125364 | C106: H0628417 | D106: P | E106: 1964 | F106: NORAINI @ RAIMAH BINTI MAJIKIT | G106: KOTA MARUDU | H106: MATUNGGONG | I106: INDARASON | J106: KG INDARASON | V106: 1
A107: 106 | B107: 640512125380 | C107: H0785467 | D107: P | E107: 1964 | F107: NORMANAH BINTI DIAM | G107: KOTA MARUDU | H107: MATUNGGONG | I107: INDARASON | J107: KG INDARASON | V107: 1
A108: 107 | B108: 640901125122 | C108: H6021343 | D108: P | E108: 1964 | F108: SALSIAH BINTI LAGUBA | G108: KOTA MARUDU | H108: MATUNGGONG | I108: INDARASON | J108: KG INDARASON | V108: 1
A109: 108 | B109: 641215125661 | C109: H0775568 | D109: L | E109: 1964 | F109: JARUMAH BIN KINTOLUK | G109: KOTA MARUDU | H109: MATUNGGONG | I109: INDARASON | J109: KG INDARASON | V109: 1
A110: 109 | B110: 650120125276 | C110: H0762230 | D110: P | E110: 1965 | F110: FALMAH BINTI RAJAH ISMAIL | G110: KOTA MARUDU | H110: MATUNGGONG | I110: INDARASON | J110: KG INDARASON | V110: 1
A111: 110 | B111: 650201125227 | C111: H0628186 | D111: L | E111: 1965 | F111: MANSOR BIN UKOK | G111: KOTA MARUDU | H111: MATUNGGONG | I111: INDARASON | J111: KG INDARASON | V111: 1
... A150: 149 | B150: 700109125016 | C150: H0765727 | D150: P | E150: 1970 | F150: MAIMUN BINTI SARPRI | G150: KOTA MARUDU | H150: MATUNGGONG | I150: INDARASON | J150: KG INDARASON | V150: 1
A151: 150 | B151: 700110126008 | D151: P | E151: 1970 | F151: NERIN BINTI KAMAHON | G151: KOTA MARUDU | H151: MATUNGGONG | I151: INDARASON | J151: KG INDARASON | V151: 1
A152: 151 | B152: 700126125181 | C152: H0773819 | D152: L | E152: 1970 | F152: MAPANSING BIN MAJJUDUL | G152: KOTA MARUDU | H152: MATUNGGONG | I152: INDARASON | J152: KG INDARASON | V152: 1
A153: 152 | B153: 700302125464 | C153: H0853888 | D153: P | E153: 1970 | F153: ROSITAH BINTI MAJIKIT | G153: KOTA MARUDU | H153: MATUNGGONG | I153: INDARASON | J153: KG INDARASON | V153: 1
A154: 153 | B154: 700316125086 | D154: P | E154: 1970 | F154: RUSNI BINTI MAJINGGIL | G154: KOTA MARUDU | H154: MATUNGGONG | I154: INDARASON | J154: KG INDARASON | V154: 1
A155: 154 | B155: 700316125465 | D155: L | E155: 1970 | F155: LEFUDIN BIN NCPIK | G155: KOTA MARUDU | H155: MATUNGGONG | I155: INDARASON | J155: KG INDARASON | V155: 1
A156: 155 | B156: 700418125300 | C156: H0753058 | D156: P | E156: 1970 | F156: JAMINAH BINTI LOEDIUN | G156: KOTA MARUDU | H156: MATUNGGONG | I156: INDARASON | J156: KG INDARASON | V156: 1
A157: 156 | B157: 700711125107 | C157: H0810729 | D157: L | E157: 1970 | F157: JATAHIR BIN ANDOU | G157: KOTA MARUDU | H157: MATUNGGONG | I157: INDARASON | J157: KG INDARASON | V157: 1
A158: 157 | B158: 700903125339 | C158: H0823778 | D158: L | E158: 1970 | F158: ADDAMAIN BIN IKON | G158: KOTA MARUDU | H158: MATUNGGONG | I158: INDARASON | J158: KG INDARASON | V158: 1
A159: 158 | B159: 700914125270 | C159: H0760178 | D159: P | E159: 1970 | F159: NORMAMAH BINTI BIDAN @ BIDIN | G159: KOTA MARUDU | H159: MATUNGGONG | I159: INDARASON | J159: KG INDARASON | V159: 1
...
