Workbook

Sheet Dashboard
A1: DASHBOARD PDM LODUNG
A3: DM | B3: LOKALITI | C3: BILANGAN PENGUNDI BERDAFTAR | D3: Anggaran Peratusan Turun Mengundi (75%) | E3: Sasaran UNDI 60% | F3: SASARAN KETUA KELUARGA (K10) | G3: JUMLAH K10 TERKINI | H3: PUTIH TERKINI | I3: Atas Pagar | J3: HITAM | K3: TIDAK KENAL | L3: Meninggal Dunia | M3: Pengundi Luar PARLIMEN | N3: Pengundi Luar SABAH | O3: PECAHAN PENGUNDI MENGIKUT UMUR
O4: 18 - 30 | P4: 31 - 45 | Q4: 46 - KEATAS
A5: LODUNG | B5: RONGGU | C5: =SUM('PDM LODUNG'!V2:V124) -> 123 | D5: =C5*75/100 -> 92.25 | E5: =SUM(D5*55/100) -> 50.7375 | F5: =SUM(E5/10) -> 5.07375 | G5: =SUM('PDM LODUNG'!L2:L124) -> 0 | H5: =SUM('PDM LODUNG'!M2:M124) -> 0 | I5: =SUM('PDM LODUNG'!N2:N124) -> 0 | J5: =SUM('PDM LODUNG'!O2:O124) -> 0 | K5: =SUM('PDM LODUNG'!P2:P124) -> 0 | L5: =SUM('PDM LODUNG'!Q2:Q124) -> 0 | M5: =SUM('PDM LODUNG'!R2:R124) -> 0 | N5: =SUM('PDM LODUNG'!S2:S124) -> 0
B6: DAHI | C6: =SUM('PDM LODUNG'!V125:V158) -> 34 | D6: =C6*75/100 -> 25.5 | E6: =SUM(D6*55/100) -> 14.025 | F6: =SUM(E6/10) -> 1.4025 | G6: =SUM('PDM LODUNG'!L125:L158) -> 0 | H6: =SUM('PDM LODUNG'!M125:M158) -> 0 | I6: =SUM('PDM LODUNG'!N125:N158) -> 0 | J6: =SUM('PDM LODUNG'!O125:O158) -> 0 | K6: =SUM('PDM LODUNG'!P125:P158) -> 0 | L6: =SUM('PDM LODUNG'!Q125:Q158) -> 0 | M6: =SUM('PDM LODUNG'!R125:R158) -> 0 | N6: =SUM('PDM LODUNG'!S125:S158) -> 0
B7: KIOPU | C7: =SUM('PDM LODUNG'!V159:V376) -> 218 | D7: =C7*75/100 -> 163.5 | E7: =SUM(D7*55/100) -> 89.925 | F7: =SUM(E7/10) -> 8.9925 | G7: =SUM('PDM LODUNG'!L159:L376) -> 0 | H7: =SUM('PDM LODUNG'!M159:M376) -> 0 | I7: =SUM('PDM LODUNG'!N159:N376) -> 0 | J7: =SUM('PDM LODUNG'!O159:O376) -> 0 | K7: =SUM('PDM LODUNG'!P159:P376) -> 0 | L7: =SUM('PDM LODUNG'!Q159:Q376) -> 0 | M7: =SUM('PDM LODUNG'!R159:R376) -> 0 | N7: =SUM('PDM LODUNG'!S159:S376) -> 0
B8: LODUNG | C8: =SUM('PDM LODUNG'!V377:V956) -> 580 | D8: =C8*75/100 -> 435 | E8: =SUM(D8*55/100) -> 239.25 | F8: =SUM(E8/10) -> 23.925 | G8: =SUM('PDM LODUNG'!L377:L956) -> 0 | H8: =SUM('PDM LODUNG'!M377:M956) -> 0 | I8: =SUM('PDM LODUNG'!N377:N956) -> 0 | J8: =SUM('PDM LODUNG'!O377:O956) -> 0 | K8: =SUM('PDM LODUNG'!P377:P956) -> 0 | L8: =SUM('PDM LODUNG'!Q377:Q956) -> 0 | M8: =SUM('PDM LODUNG'!R377:R956) -> 0 | N8: =SUM('PDM LODUNG'!S377:S956) -> 0
B9: PITURU | C9: =SUM('PDM LODUNG'!V957:V1151) -> 195 | D9: =C9*75/100 -> 146.25 | E9: =SUM(D9*55/100) -> 80.4375 | F9: =SUM(E9/10) -> 8.04375 | G9: =SUM('PDM LODUNG'!L957:L1151) -> 0 | H9: =SUM('PDM LODUNG'!M957:M1151) -> 0 | I9: =SUM('PDM LODUNG'!N957:N1151) -> 0 | J9: =SUM('PDM LODUNG'!O957:O1151) -> 0 | K9: =SUM('PDM LODUNG'!P957:P1151) -> 0 | L9: =SUM('PDM LODUNG'!Q957:Q1151) -> 0 | M9: =SUM('PDM LODUNG'!R957:R1151) -> 0 | N9: =SUM('PDM LODUNG'!S957:S1151) -> 0
B10: DUMPIRING | C10: =SUM('PDM LODUNG'!V1152:V1297) -> 146 | D10: =C10*75/100 -> 109.5 | E10: =SUM(D10*55/100) -> 60.225 | F10: =SUM(E10/10) -> 6.0225 | G10: =SUM('PDM LODUNG'!L1152:L1297) -> 0 | H10: =SUM('PDM LODUNG'!M1152:M1297) -> 0 | I10: =SUM('PDM LODUNG'!N1152:N1297) -> 0 | J10: =SUM('PDM LODUNG'!O1152:O1297) -> 0 | K10: =SUM('PDM LODUNG'!P1152:P1297) -> 0 | L10: =SUM('PDM LODUNG'!Q1152:Q1297) -> 0 | M10: =SUM('PDM LODUNG'!R1152:R1297) -> 0 | N10: =SUM('PDM LODUNG'!S1152:S1297) -> 0
B11: LODUNG TOGUDON | C11: =SUM('PDM LODUNG'!V1298:V1377) -> 80 | D11: =C11*75/100 -> 60 | E11: =SUM(D11*55/100) -> 33 | F11: =SUM(E11/10) -> 3.3 | G11: =SUM('PDM LODUNG'!L1298:L1377) -> 0 | H11: =SUM('PDM LODUNG'!M1298:M1377) -> 0 | I11: =SUM('PDM LODUNG'!N1298:N1377) -> 0 | J11: =SUM('PDM LODUNG'!O1298:O1377) -> 0 | K11: =SUM('PDM LODUNG'!P1298:P1377) -> 0 | L11: =SUM('PDM LODUNG'!Q1298:Q1377) -> 0 | M11: =SUM('PDM LODUNG'!R1298:R1377) -> 0 | N11: =SUM('PDM LODUNG'!S1298:S1377) -> 0
B12: KUSILAD DARAT | C12: =SUM('PDM LODUNG'!V1378:V1433) -> 56 | D12: =C12*75/100 -> 42 | E12: =SUM(D12*55/100) -> 23.1 | F12: =SUM(E12/10) -> 2.31 | G12: =SUM('PDM LODUNG'!L1378:L1433) -> 0 | H12: =SUM('PDM LODUNG'!M1378:M1433) -> 0 | I12: =SUM('PDM LODUNG'!N1378:N1433) -> 0 | J12: =SUM('PDM LODUNG'!O1378:O1433) -> 0 | K12: =SUM('PDM LODUNG'!P1378:P1433) -> 0 | L12: =SUM('PDM LODUNG'!Q1378:Q1433) -> 0 | M12: =SUM('PDM LODUNG'!R1378:R1433) -> 0 | N12: =SUM('PDM LODUNG'!S1378:S1433) -> 0
A13: JUMLAH | C13: =SUM(C5:C12) -> 1432 | D13: =SUM(D5:D12) -> 1074 | E13: =SUM(E5:E12) -> 590.7 | F13: =SUM(F5:F12) -> 59.07 | G13: =SUM(G5:G12) -> 0 | H13: =SUM(H5:H12) -> 0 | I13: =SUM(I5:I12) -> 0 | J13: =SUM(J5:J12) -> 0 | ... M13: =SUM(M5:M12) -> 0 | O13: =SUM(O5:O12) -> 0 | P13: =SUM(P5:P12) -> 0 | Q13: =SUM(Q5:Q12) -> 0

Sheet PDM LODUNG
A1: NO | B1: NO KP | C1: IC LAMA | D1: S | E1: LAHIR | F1: NAMA PENUH | G1: PARLIMEN | H1: DUN | I1: DM | J1: LOKALITI | K1: NO TELEFON | L1: K10 | M1: P | N1: AP | O1: H | P1: TAK KENAL | Q1: X DUNIA | R1: SABAH LABUAN | S1: LUAR SABAH | T1: Perincian | U1: TAGING | V1: D | W1: TAMBANG | X1: SEWA KERETA | Y1: Delivered
A2: 1 | B2: 181219125066 | C2: H0262175 | D2: P | E2: 1918 | F2: YUMOKBONG BINTI BOOI | G2: KOTA MARUDU | H2: MATUNGGONG | I2: LODUNG | J2: KG RONGGU | V2: 1
A3: 2 | B3: 400705125544 | C3: H0135632 | D3: P | E3: 1940 | F3: UNDABIS BINTI MAAN | G3: KOTA MARUDU | H3: MATUNGGONG | I3: LODUNG | J3: KG RONGGU | V3: 1
A4: 3 | B4: 410103125255 | C4: H0175333 | D4: L | E4: 1941 | F4: TOVODSOH BIN LUMANAH | G4: KOTA MARUDU | H4: MATUNGGONG | I4: LODUNG | J4: KG RONGGU | V4: 1
A5: 4 | B5: 430304125268 | C5: H0263096 | D5: P | E5: 1943 | F5: VUNSIJAH BINTI SUKU | G5: KOTA MARUDU | H5: MATUNGGONG | I5: LODUNG | J5: KG RONGGU | V5: 1
A6: 5 | B6: 441228125218 | C6: H0408523 | D6: P | E6: 1944 | F6: AH CHEMIN BINTI AHSA | G6: KOTA MARUDU | H6: MATUNGGONG | I6: LODUNG | J6: KG RONGGU | V6: 1
A7: 6 | B7: 450420125124 | C7: H0263020 | D7: P | E7: 1945 | F7: ONGUNDOYI BINTI MAAN | G7: KOTA MARUDU | H7: MATUNGGONG | I7: LODUNG | J7: KG RONGGU | V7: 1
A8: 7 | B8: 480507125095 | C8: H0279821 | D8: L | E8: 1948 | F8: LADA BIN LADILAK | G8: KOTA MARUDU | H8: MATUNGGONG | I8: LODUNG | J8: KG RONGGU | V8: 1
A9: 8 | B9: 501231125325 | C9: H0261928 | D9: L | E9: 1950 | F9: KILIM BIN UMBAUAN | G9: KOTA MARUDU | H9: MATUNGGONG | I9: LODUNG | J9: KG RONGGU | V9: 1
A10: 9 | B10: 511229125130 | C10: H0278906 | D10: P | E10: 1951 | F10: UZAI BINTI DAANG | G10: KOTA MARUDU | H10: MATUNGGONG | I10: LODUNG | J10: KG RONGGU | V10: 1
A11: 10 | B11: 570426125033 | C11: H0210994 | D11: L | E11: 1957 | F11: LEE TZE KIUN | G11: KOTA MARUDU | H11: MATUNGGONG | I11: LODUNG | J11: KG RONGGU | V11: 1
A12: 11 | B12: 570525125186 | C12: H0428712 | D12: P | E12: 1957 | F12: UYAH @ HELEN BINTI TAMPURUN | G12: KOTA MARUDU | H12: MATUNGGONG | I12: LODUNG | J12: KG RONGGU | V12: 1
A13: 12 | B13: 570623125163 | C13: H0143098 | D13: L | E13: 1957 | F13: WONG KUI HI @ WONG THEN FAH | G13: KOTA MARUDU | H13: MATUNGGONG | I13: LODUNG | J13: KG RONGGU | V13: 1
... A33: 32 | B33: 780111125704 | C33: H0967294 | D33: P | E33: 1978 | F33: ARIVIA MONGUBING | G33: KOTA MARUDU | H33: MATUNGGONG | I33: LODUNG | J33: KG RONGGU | V33: 1
A34: 33 | B34: 000115120206 | D34: P | E34: 2000 | F34: CHRISTI BINTI JOHNING | G34: KOTA MARUDU | H34: MATUNGGONG | I34: LODUNG | J34: KG RONGGU | V34: 1
A35: 34 | B35: 000804122071 | D35: L | E35: 2000 | F35: WELTER LEE | G35: KOTA MARUDU | H35: MATUNGGONG | I35: LODUNG | J35: KG RONGGU | V35: 1
A36: 35 | B36: 000819121020 | D36: P | E36: 2000 | F36: CALOREN BINTI JOHN | G36: KOTA MARUDU | H36: MATUNGGONG | I36: LODUNG | J36: KG RONGGU | V36: 1
A37: 36 | B37: 000926070927 | D37: L | E37: 2000 | F37: ELVIN DONIS | G37: KOTA MARUDU | H37: MATUNGGONG | I37: LODUNG | J37: KG RONGGU | V37: 1
A38: 37 | B38: 010616120553 | D38: L | E38: 2001 | F38: ALFRED MUSILIN | G38: KOTA MARUDU | H38: MATUNGGONG | I38: LODUNG | J38: KG RONGGU | V38: 1
A39: 38 | B39: 010818121677 | D39: L | E39: 2001 | F39: OWNELL BRYAN | G39: KOTA MARUDU | H39: MATUNGGONG | I39: LODUNG | J39: KG RONGGU | V39: 1
A40: 39 | B40: 010820120286 | D40: P | E40: 2001 | F40: JANE BINTI JOHNING | G40: KOTA MARUDU | H40: MATUNGGONG | I40: LODUNG | J40: KG RONGGU | V40: 1
A41: 40 | B41: 011018121403 | D41: L | E41: 2001 | F41: ERWIN ALFRED | G41: KOTA MARUDU | H41: MATUNGGONG | I41: LODUNG | J41: KG RONGGU | V41: 1
A42: 41 | B42: 020109120427 | D42: L | E42: 2002 | F42: JERYSON BIN BIDIN | G42: KOTA MARUDU | H42: MATUNGGONG | I42: LODUNG | J42: KG RONGGU | V42: 1
A43: 42 | B43: 020820120293 | D43: L | E43: 2002 | F43: LIUSTEN BIN MARTIN | G43: KOTA MARUDU | H43: MATUNGGONG | I43: LODUNG | J43: KG RONGGU | V43: 1
A44: 43 | B44: 021101120427 | D44: L | E44: 2002 | F44: AS MIZAL LODIRIS | G44: KOTA MARUDU | H44: MATUNGGONG | I44: LODUNG | J44: KG RONGGU | V44: 1
A45: 44 | B45: 030721120430 | D45: P | E45: 2003 | F45: ANGELLY WONG FUNG FUNG | G45: KOTA MARUDU | H45: MATUNGGONG | I45: LODUNG | J45: KG RONGGU | V45: 1
... A51: 52 | B51: 071012121298 | D51: P | E51: 2007 | F51: MICHLEE KROCE MUSILIN | G51: KOTA MARUDU | H51: MATUNGGONG | I51: LODUNG | J51: KG RONGGU | V51: 1
A52: 53 | B52: 750322125256 | C52: H0948398 | D52: P | E52: 1975 | F52: LILY FREDORIN | G52: KOTA MARUDU | H52: MATUNGGONG | I52: LODUNG | J52: KG RONGGU | V52: 1
A53: 54 | B53: 761031125129 | D53: L | E53: 1976 | F53: ELVIS @ RICMAN REYES BIN OLISIN @ JOSEPH | G53: KOTA MARUDU | H53: MATUNGGONG | I53: LODUNG | J53: KG RONGGU | V53: 1
A54: 56 | B54: 800205125356 | D54: P | E54: 1980 | F54: JAINIE BINTI OMPORILENG | G54: KOTA MARUDU | H54: MATUNGGONG | I54: LODUNG | J54: KG RONGGU | V54: 1
A55: 57 | B55: 800612125775 | D55: L | E55: 1980 | F55: MADERIM BIN KILIM | G55: KOTA MARUDU | H55: MATUNGGONG | I55: LODUNG | J55: KG RONGGU | V55: 1
A56: 58 | B56: 800616125019 | D56: L | E56: 1980 | F56: ZAINAL BIN MOLUPIN | G56: KOTA MARUDU | H56: MATUNGGONG | I56: LODUNG | J56: KG RONGGU | V56: 1
A57: 59 | B57: 810819125755 | D57: L | E57: 1981 | F57: ALEXIUS BOLA | G57: KOTA MARUDU | H57: MATUNGGONG | I57: LODUNG | J57: KG RONGGU | V57: 1
A58: 60 | B58: 811204126043 | D58: L | E58: 1981 | F58: JEMISUS BIN LAPUSING | G58: KOTA MARUDU | H58: MATUNGGONG | I58: LODUNG | J58: KG RONGGU | V58: 1
A59: 61 | B59: 811225125787 | D59: L | E59: 1981 | F59: RONNI BIN JOHN | G59: KOTA MARUDU | H59: MATUNGGONG | I59: LODUNG | J59: KG RONGGU | V59: 1
A60: 63 | B60: 820704126685 | D60: L | E60: 1982 | F60: ROLAND BIN NAIH | G60: KOTA MARUDU | H60: MATUNGGONG | I60: LODUNG | J60: KG RONGGU | V60: 1
A61: 64 | B61: 820811125151 | D61: L | E61: 1982 | F61: JUANIS LEE SUI KONG | G61: KOTA MARUDU | H61: MATUNGGONG | I61: LODUNG | J61: KG RONGGU | V61: 1
A62: 65 | B62: 820818125429 | D62: L | E62: 1982 | F62: DORRIS BIN LASANIM | G62: KOTA MARUDU | H62: MATUNGGONG | I62: LODUNG | J62: KG RONGGU | V62: 1
A63: 66 | B63: 821009125570 | D63: P | E63: 1982 | F63: TRACY BINTI TAYAH | G63: KOTA MARUDU | H63: MATUNGGONG | I63: LODUNG | J63: KG RONGGU | V63: 1
A64: 67 | B64: 821122125951 | D64: L | E64: 1982 | F64: EDWIN BIN OLISIN @ JOSEPH | G64: KOTA MARUDU | H64: MATUNGGONG | I64: LODUNG | J64: KG RONGGU | V64: 1
...
