Workbook

Sheet Dashboard
A1: DASHBOARD PDM INDARASON
A3: DM | B3: LOKALITI | C3: BILANGAN PENGUNDI BERDAFTAR | D3: Anggaran Peratusan Turun Mengundi (75%) | E3: Sasaran UNDI 60% | F3: SASARAN KETUA KELUARGA (K10) | G3: JUMLAH K10 TERKINI | H3: PUTIH TERKINI | I3: Atas Pagar | J3: HITAM | K3: TIDAK KENAL | L3: Meninggal Dunia | M3: Pengundi Luar PARLIMEN | N3: Pengundi Luar SABAH | O3: PECAHAN PENGUNDI MENGIKUT UMUR
O4: 18 - 30 | P4: 31 - 45 | Q4: 46 - KEATAS
A5: KANDAWAYON | B5: BONDUK | C5: =SUM('PDM Kandawayon'!V2:V147) -> 146 | D5: =C5*75/100 -> 109.5 | E5: =SUM(D5*55/100) -> 60.225 | F5: =SUM(E5/10) -> 6.0225 | G5: =SUM('PDM Kandawayon'!L2:L147) -> 0 | H5: =SUM('PDM Kandawayon'!M2:M147) -> 0 | I5: =SUM('PDM Kandawayon'!N2:N147) -> 0 | J5: =SUM('PDM Kandawayon'!O2:O147) -> 0 | K5: =SUM('PDM Kandawayon'!P2:P147) -> 0 | L5: =SUM('PDM Kandawayon'!Q2:Q147) -> 0 | M5: =SUM('PDM Kandawayon'!R2:R147) -> 0 | N5: =SUM('PDM Kandawayon'!S2:S147) -> 0
B6: KANDAWAYON | C6: =SUM('PDM Kandawayon'!V148:V633) -> 486 | D6: =C6*75/100 -> 364.5 | E6: =SUM(D6*55/100) -> 200.475 | F6: =SUM(E6/10) -> 20.0475 | G6: =SUM('PDM Kandawayon'!L148:L633) -> 0 | H6: =SUM('PDM Kandawayon'!M148:M633) -> 0 | I6: =SUM('PDM Kandawayon'!N148:N633) -> 0 | J6: =SUM('PDM Kandawayon'!O148:O633) -> 0 | K6: =SUM('PDM Kandawayon'!P148:P633) -> 0 | L6: =SUM('PDM Kandawayon'!Q148:Q633) -> 0 | M6: =SUM('PDM Kandawayon'!R148:R633) -> 0 | N6: =SUM('PDM Kandawayon'!S148:S633) -> 0
B7: PARAPAT | C7: =SUM('PDM Kandawayon'!V634:V1037) -> 404 | D7: =C7*75/100 -> 303 | E7: =SUM(D7*55/100) -> 166.65 | F7: =SUM(E7/10) -> 16.665 | G7: =SUM('PDM Kandawayon'!L634:L1037) -> 0 | H7: =SUM('PDM Kandawayon'!M634:M1037) -> 0 | I7: =SUM('PDM Kandawayon'!N634:N1037) -> 0 | J7: =SUM('PDM Kandawayon'!O634:O1037) -> 0 | K7: =SUM('PDM Kandawayon'!P634:P1037) -> 0 | L7: =SUM('PDM Kandawayon'!Q634:Q1037) -> 0 | M7: =SUM('PDM Kandawayon'!R634:R1037) -> 0 | N7: =SUM('PDM Kandawayon'!S634:S1037) -> 0
B8: RUKOM DARAT | C8: =SUM('PDM Kandawayon'!V1038:V1072) -> 35 | D8: =C8*75/100 -> 26.25 | E8: =SUM(D8*55/100) -> 14.4375 | F8: =SUM(E8/10) -> 1.44375 | G8: =SUM('PDM Kandawayon'!L1038:L1072) -> 0 | H8: =SUM('PDM Kandawayon'!M1038:M1072) -> 0 | I8: =SUM('PDM Kandawayon'!N1038:N1072) -> 0 | J8: =SUM('PDM Kandawayon'!O1038:O1072) -> 0 | K8: =SUM('PDM Kandawayon'!P1038:P1072) -> 0 | L8: =SUM('PDM Kandawayon'!Q1038:Q1072) -> 0 | M8: =SUM('PDM Kandawayon'!R1038:R1072) -> 0 | N8: =SUM('PDM Kandawayon'!S1038:S1072) -> 0
B9: KUALA PARAPAT | C9: =SUM('PDM Kandawayon'!V1073:V1082) -> 10 | D9: =C9*75/100 -> 7.5 | E9: =SUM(D9*55/100) -> 4.125 | F9: =SUM(E9/10) -> 0.4125 | G9: =SUM('PDM Kandawayon'!L1073:L1082) -> 0 | H9: =SUM('PDM Kandawayon'!M1073:M1082) -> 0 | I9: =SUM('PDM Kandawayon'!N1073:N1082) -> 0 | J9: =SUM('PDM Kandawayon'!O1073:O1082) -> 0 | K9: =SUM('PDM Kandawayon'!P1073:P1082) -> 0 | L9: =SUM('PDM Kandawayon'!Q1073:Q1082) -> 0 | M9: =SUM('PDM Kandawayon'!R1073:R1082) -> 0 | N9: =SUM('PDM Kandawayon'!S1073:S1082) -> 0
A10: JUMLAH | C10: =SUM(C5:C9) -> 1081 | D10: =SUM(D5:D9) -> 810.75 | E10: =SUM(E5:E9) -> 445.9125 | F10: =SUM(F5:F9) -> 44.59125 | G10: =SUM(G5:G9) -> 0 | H10: =SUM(H5:H9) -> 0 | I10: =SUM(I5:I9) -> 0 | J10: =SUM(J5:J9) -> 0 | ... M10: =SUM(M5:M9) -> 0 | O10: =SUM(O5:O9) -> 0 | P10: =SUM(P5:P9) -> 0 | Q10: =SUM(Q5:Q9) -> 0

Sheet PDM Kandawayon
A1: NO | B1: NO KP | C1: IC LAMA | D1: S | E1: LAHIR | F1: NAMA PENUH | G1: PARLIMEN | H1: DUN | I1: DM | J1: LOKALITI | K1: NO TELEFON | L1: K10 | M1: P | N1: AP | O1: H | P1: TAK KENAL | Q1: X DUNIA | R1: SABAH LABUAN | S1: LUAR SABAH | T1: Perincian | U1: TAGING | V1: D | W1: TAMBANG | X1: SEWA KERETA | Y1: Delivered
A2: 1 | B2: 390331125083 | C2: H0268392 | D2: L | E2: 1939 | F2: YASIMPAK BIN UBAIN | G2: KOTA MARUDU | H2: MATUNGGONG | I2: KANDAWAYON | J2: KG BONDUK | V2: 1
A3: 2 | B3: 430513125168 | C3: H0258768 | D3: P | E3: 1943 | F3: ENDISIN BINTI GANGAT | G3: KOTA MARUDU | H3: MATUNGGONG | I3: KANDAWAYON | J3: KG BONDUK | V3: 1
A4: 3 | B4: 431219125241 | C4: H0408004 | D4: L | E4: 1943 | F4: MILE BIN MAGALI | G4: KOTA MARUDU | H4: MATUNGGONG | I4: KANDAWAYON | J4: KG BONDUK | V4: 1
A5: 4 | B5: 510429125173 | C5: H0261544 | D5: L | E5: 1951 | F5: KINSIM BIN BIDIN | G5: KOTA MARUDU | H5: MATUNGGONG | I5: KANDAWAYON | J5: KG BONDUK | V5: 1
A6: 5 | B6: 521127125286 | C6: H0261677 | D6: P | E6: 1952 | F6: LUMBIHI BINTI TOVODSO | G6: KOTA MARUDU | H6: MATUNGGONG | I6: KANDAWAYON | J6: KG BONDUK | V6: 1
A7: 6 | B7: 540429125218 | C7: H0260631 | D7: P | E7: 1954 | F7: SINORILIN BINTI MAMKUL | G7: KOTA MARUDU | H7: MATUNGGONG | I7: KANDAWAYON | J7: KG BONDUK | V7: 1
A8: 7 | B8: 550417125455 | C8: H0171876 | D8: L | E8: 1955 | F8: MARASUN BIN GARIM | G8: KOTA MARUDU | H8: MATUNGGONG | I8: KANDAWAYON | J8: KG BONDUK | V8: 1
A9: 8 | B9: 560619125225 | C9: H0387781 | D9: L | E9: 1956 | F9: INGKU BIN MANGEIAT | G9: KOTA MARUDU | H9: MATUNGGONG | I9: KANDAWAYON | J9: KG BONDUK | V9: 1
A10: 9 | B10: 560715125620 | C10: H0258770 | D10: P | E10: 1956 | F10: YUNOI BINTI BIDIN | G10: KOTA MARUDU | H10: MATUNGGONG | I10: KANDAWAYON | J10: KG BONDUK | V10: 1
A11: 10 | B11: 580221125135 | C11: H0652531 | D11: L | E11: 1958 | F11: AMAM BIN RUMANSUN | G11: KOTA MARUDU | H11: MATUNGGONG | I11: KANDAWAYON | J11: KG BONDUK | V11: 1
A12: 11 | B12: 590301126217 | C12: H0458637 | D12: L | E12: 1959 | F12: NOGIRIS BIN SABALA @ STEPHEN NOGIRIS | G12: KOTA MARUDU | H12: MATUNGGONG | I12: KANDAWAYON | J12: KG BONDUK | V12: 1
A13: 12 | B13: 600517125666 | C13: H0442237 | D13: P | E13: 1960 | F13: ALIMOI BINTI UNUKBAR | G13: KOTA MARUDU | H13: MATUNGGONG | I13: KANDAWAYON | J13: KG BONDUK | V13: 1
... A22: 21 | B22: 701128125761 | C22: H0969231 | D22: L | E22: 1970 | F22: JOLIUS BIN BIDIN | G22: KOTA MARUDU | H22: MATUNGGONG | I22: KANDAWAYON | J22: KG BONDUK | V22: 1
A23: 22 | B23: 740907125033 | D23: L | E23: 1974 | F23: JOMURI BIN YASIMPAK | G23: KOTA MARUDU | H23: MATUNGGONG | I23: KANDAWAYON | J23: KG BONDUK | V23: 1
A24: 23 | B24: 741129125401 | C24: H0906961 | D24: L | E24: 1974 | F24: WENSON BIN YONHUJI | G24: KOTA MARUDU | H24: MATUNGGONG | I24: KANDAWAYON | J24: KG BONDUK | V24: 1
A25: 24 | B25: 750521125507 | C25: H0960356 | D25: L | E25: 1975 | F25: JHORIFLIE BIN SANI | G25: KOTA MARUDU | H25: MATUNGGONG | I25: KANDAWAYON | J25: KG BONDUK | V25: 1
A26: 25 | B26: 751107125354 | C26: H0967413 | D26: P | E26: 1975 | F26: NURA BINTI KATIM | G26: KOTA MARUDU | H26: MATUNGGONG | I26: KANDAWAYON | J26: KG BONDUK | V26: 1
A27: 26 | B27: 770217125244 | C27: H0931622 | D27: P | E27: 1977 | F27: MERIN BINTI MAGUMPIS | G27: KOTA MARUDU | H27: MATUNGGONG | I27: KANDAWAYON | J27: KG BONDUK | V27: 1
A28: 27 | B28: 000301120402 | D28: P | E28: 2000 | F28: JULIANCCA RAFNNIE JARUN | G28: KOTA MARUDU | H28: MATUNGGONG | I28: KANDAWAYON | J28: KG BONDUK | V28: 1
A29: 28 | B29: 000610120561 | D29: L | E29: 2000 | F29: LEVIONNY BIN JOLIUS | G29: KOTA MARUDU | H29: MATUNGGONG | I29: KANDAWAYON | J29: KG BONDUK | V29: 1
A30: 29 | B30: 001106120532 | D30: P | E30: 2000 | F30: LENNY ELLENA JABILIN | G30: KOTA MARUDU | H30: MATUNGGONG | I30: KANDAWAYON | J30: KG BONDUK | V30: 1
A31: 30 | B31: 001109120861 | D31: L | E31: 2000 | F31: ANDEY YONG VUI HIN | G31: KOTA MARUDU | H31: MATUNGGONG | I31: KANDAWAYON | J31: KG BONDUK | V31: 1
A32: 31 | B32: 001113121074 | D32: P | E32: 2000 | F32: AMRIA BINTI ABD.RAZAK | G32: KOTA MARUDU | H32: MATUNGGONG | I32: KANDAWAYON | J32: KG BONDUK | V32: 1
A33: 32 | B33: 010223120624 | D33: P | E33: 2001 | F33: X .FLERISHA BINTI JOMURI | G33: KOTA MARUDU | H33: MATUNGGONG | I33: KANDAWAYON | J33: KG BONDUK | V33: 1
A34: 33 | B34: 010503120282 | D34: P | E34: 2001 | F34: AMELAHSIA MAJUNING | G34: KOTA MARUDU | H34: MATUNGGONG | I34: KANDAWAYON | J34: KG BONDUK | V34: 1
A35: 34 | B35: 010604120863 | D35: L | E35: 2001 | F35: AZRIN BIN UNANG | G35: KOTA MARUDU | H35: MATUNGGONG | I35: KANDAWAYON | J35: KG BONDUK | V35: 1
A36: 35 | B36: 010611120888 | D36: P | E36: 2001 | F36: FEBEIANN INGKU | G36: KOTA MARUDU | H36: MATUNGGONG | I36: KANDAWAYON | J36: KG BONDUK | V36: 1
A37: 36 | B37: 010815120441 | D37: L | E37: 2001 | F37: JERROMMIE RMM JARUN | G37: KOTA MARUDU | H37: MATUNGGONG | I37: KANDAWAYON | J37: KG BONDUK | V37: 1
A38: 37 | B38: 011112120706 | D38: P | E38: 2001 | F38: MARLISA BINTI OSITAK | G38: KOTA MARUDU | H38: MATUNGGONG | I38: KANDAWAYON | J38: KG BONDUK | V38: 1
A39: 38 | B39: 020520120953 | D39: L | E39: 2002 | F39: MARELVEN CHRISTOPER TEOFILUS | G39: KOTA MARUDU | H39: MATUNGGONG | I39: KANDAWAYON | J39: KG BONDUK | V39: 1
... A55: 54 | B55: 070622120845 | D55: L | E55: 2007 | F55: CHRISTIAN HANSSEN SALVISTER | G55: KOTA MARUDU | H55: MATUNGGONG | I55: KANDAWAYON | J55: KG BONDUK | V55: 1
A56: 55 | B56: 650903126021 | C56: H0706405 | D56: L | E56: 1965 | F56: MAJUNING BIN BIDIN | G56: KOTA MARUDU | H56: MATUNGGONG | I56: KANDAWAYON | J56: KG BONDUK | V56: 1
A57: 56 | B57: 661127125459 | C57: H0689131 | D57: L | E57: 1966 | F57: JABILIN BIN GARIM | G57: KOTA MARUDU | H57: MATUNGGONG | I57: KANDAWAYON | J57: KG BONDUK | V57: 1
A58: 57 | B58: 670911125780 | D58: P | E58: 1967 | F58: FENIE BINTI MOJUNGKIL | G58: KOTA MARUDU | H58: MATUNGGONG | I58: KANDAWAYON | J58: KG BONDUK | V58: 1
A59: 58 | B59: 671120125965 | C59: H0718661 | D59: L | E59: 1967 | F59: TEOFILUS BIN ONGUMPI | G59: KOTA MARUDU | H59: MATUNGGONG | I59: KANDAWAYON | J59: KG BONDUK | V59: 1
A60: 59 | B60: 701121125531 | C60: H0769232 | D60: L | E60: 1970 | F60: JENSON BIN SANDUYU @ ALI | G60: KOTA MARUDU | H60: MATUNGGONG | I60: KANDAWAYON | J60: KG BONDUK | V60: 1
A61: 60 | B61: 720717125421 | C61: H0865374 | D61: L | E61: 1972 | F61: JOLIUS BIN YOJUNPIN | G61: KOTA MARUDU | H61: MATUNGGONG | I61: KANDAWAYON | J61: KG BONDUK | V61: 1
A62: 61 | B62: 730830125406 | C62: H0853874 | D62: P | E62: 1973 | F62: SUSANA BINTI SUKIN | G62: KOTA MARUDU | H62: MATUNGGONG | I62: KANDAWAYON | J62: KG BONDUK | V62: 1
A63: 62 | B63: 750527125807 | D63: L | E63: 1975 | F63: SAMUIL BIN MION | G63: KOTA MARUDU | H63: MATUNGGONG | I63: KANDAWAYON | J63: KG BONDUK | V63: 1
...
